 Your service is live ðŸŽ‰
==> 
==> ///////////////////////////////////////////////////////////
==> 
==> Available at your primary URL https://quiz-6fxa.onrender.com
==> 
==> ///////////////////////////////////////////////////////////
2025-10-04 09:16:00,458 - apscheduler.executors.default - INFO - Running job "send_automated_quiz (trigger: interval[0:30:00], next run at: 2025-10-04 09:46:00 UTC)" (scheduled at 2025-10-04 09:16:00.448254+00:00)
2025-10-04 09:16:00,458 - src.bot.handlers - INFO - Starting automated quiz broadcast to 0 active chats
2025-10-04 09:16:00,458 - src.bot.handlers - INFO - Completed automated quiz broadcast cycle
2025-10-04 09:16:00,458 - apscheduler.executors.default - INFO - Job "send_automated_quiz (trigger: interval[0:30:00], next run at: 2025-10-04 09:46:00 UTC)" executed successfully
2025-10-04 09:16:18,996 - telegram.ext.Updater - ERROR - Exception happened while polling for updates.
Traceback (most recent call last):
  File "/root/.local/lib/python3.11/site-packages/telegram/ext/_utils/networkloop.py", line 134, in network_retry_loop
    await do_action()
  File "/root/.local/lib/python3.11/site-packages/telegram/ext/_utils/networkloop.py", line 127, in do_action
    action_cb_task.result()
  File "/root/.local/lib/python3.11/site-packages/telegram/ext/_updater.py", line 340, in polling_action_cb
    updates = await self.bot.get_updates(
              ^^^^^^^^^^^^^^^^^^^^^^^^^^^
  File "/root/.local/lib/python3.11/site-packages/telegram/ext/_extbot.py", line 676, in get_updates
    updates = await super().get_updates(
              ^^^^^^^^^^^^^^^^^^^^^^^^^^
  File "/root/.local/lib/python3.11/site-packages/telegram/_bot.py", line 4780, in get_updates
    await self._post(
  File "/root/.local/lib/python3.11/site-packages/telegram/_bot.py", line 703, in _post
    return await self._do_post(
           ^^^^^^^^^^^^^^^^^^^^
  File "/root/.local/lib/python3.11/site-packages/telegram/ext/_extbot.py", line 372, in _do_post
    return await super()._do_post(
           ^^^^^^^^^^^^^^^^^^^^^^^
  File "/root/.local/lib/python3.11/site-packages/telegram/_bot.py", line 732, in _do_post
    result = await request.post(
             ^^^^^^^^^^^^^^^^^^^
  File "/root/.local/lib/python3.11/site-packages/telegram/request/_baserequest.py", line 198, in post
    result = await self._request_wrapper(
             ^^^^^^^^^^^^^^^^^^^^^^^^^^^^
  File "/root/.local/lib/python3.11/site-packages/telegram/request/_baserequest.py", line 375, in _request_wrapper
    raise exception
telegram.error.Conflict: Conflict: terminated by setWebhook request
2025-10-04 09:16:23,177 - telegram.ext.Updater - ERROR - Exception happened while polling for updates.
Traceback (most recent call last):
  File "/root/.local/lib/python3.11/site-packages/telegram/ext/_utils/networkloop.py", line 134, in network_retry_loop
    await do_action()
  File "/root/.local/lib/python3.11/site-packages/telegram/ext/_utils/networkloop.py", line 127, in do_action
    action_cb_task.result()
  File "/root/.local/lib/python3.11/site-packages/telegram/ext/_updater.py", line 340, in polling_action_cb
    updates = await self.bot.get_updates(
              ^^^^^^^^^^^^^^^^^^^^^^^^^^^
  File "/root/.local/lib/python3.11/site-packages/telegram/ext/_extbot.py", line 676, in get_updates
    updates = await super().get_updates(
              ^^^^^^^^^^^^^^^^^^^^^^^^^^
  File "/root/.local/lib/python3.11/site-packages/telegram/_bot.py", line 4780, in get_updates
    await self._post(
  File "/root/.local/lib/python3.11/site-packages/telegram/_bot.py", line 703, in _post
    return await self._do_post(
           ^^^^^^^^^^^^^^^^^^^^
  File "/root/.local/lib/python3.11/site-packages/telegram/ext/_extbot.py", line 372, in _do_post
    return await super()._do_post(
           ^^^^^^^^^^^^^^^^^^^^^^^
  File "/root/.local/lib/python3.11/site-packages/telegram/_bot.py", line 732, in _do_post
    result = await request.post(
             ^^^^^^^^^^^^^^^^^^^
  File "/root/.local/lib/python3.11/site-packages/telegram/request/_baserequest.py", line 198, in post
    result = await self._request_wrapper(
             ^^^^^^^^^^^^^^^^^^^^^^^^^^^^
  File "/root/.local/lib/python3.11/site-packages/telegram/request/_baserequest.py", line 375, in _request_wrapper
    raise exception
telegram.error.Conflict: Conflict: can't use getUpdates method while webhook is active; use deleteWebhook to delete the webhook first
2025-10-04 09:16:24,840 - telegram.ext.Updater - ERROR - Exception happened while polling for updates.
Traceback (most recent call last):
  File "/root/.local/lib/python3.11/site-packages/telegram/ext/_utils/networkloop.py", line 134, in network_retry_loop
    await do_action()
  File "/root/.local/lib/python3.11/site-packages/telegram/ext/_utils/networkloop.py", line 127, in do_action
    action_cb_task.result()
  File "/root/.local/lib/python3.11/site-packages/telegram/ext/_updater.py", line 340, in polling_action_cb
    updates = await self.bot.get_updates(
              ^^^^^^^^^^^^^^^^^^^^^^^^^^^
  File "/root/.local/lib/python3.11/site-packages/telegram/ext/_extbot.py", line 676, in get_updates
    updates = await super().get_updates(
              ^^^^^^^^^^^^^^^^^^^^^^^^^^
  File "/root/.local/lib/python3.11/site-packages/telegram/_bot.py", line 4780, in get_updates
    await self._post(
  File "/root/.local/lib/python3.11/site-packages/telegram/_bot.py", line 703, in _post
    return await self._do_post(
           ^^^^^^^^^^^^^^^^^^^^
  File "/root/.local/lib/python3.11/site-packages/telegram/ext/_extbot.py", line 372, in _do_post
    return await super()._do_post(
           ^^^^^^^^^^^^^^^^^^^^^^^
  File "/root/.local/lib/python3.11/site-packages/telegram/_bot.py", line 732, in _do_post
    result = await request.post(
             ^^^^^^^^^^^^^^^^^^^
  File "/root/.local/lib/python3.11/site-packages/telegram/request/_baserequest.py", line 198, in post
    result = await self._request_wrapper(
             ^^^^^^^^^^^^^^^^^^^^^^^^^^^^
  File "/root/.local/lib/python3.11/site-packages/telegram/request/_baserequest.py", line 375, in _request_wrapper
    raise exception
telegram.error.Conflict: Conflict: can't use getUpdates method while webhook is active; use deleteWebhook to delete the webhook first
2025-10-04 09:16:30,254 - telegram.ext.Updater - ERROR - Exception happened while polling for updates.
Traceback (most recent call last):
  File "/root/.local/lib/python3.11/site-packages/telegram/ext/_utils/networkloop.py", line 134, in network_retry_loop
    await do_action()
  File "/root/.local/lib/python3.11/site-packages/telegram/ext/_utils/networkloop.py", line 127, in do_action
    action_cb_task.result()
  File "/root/.local/lib/python3.11/site-packages/telegram/ext/_updater.py", line 340, in polling_action_cb
    updates = await self.bot.get_updates(
              ^^^^^^^^^^^^^^^^^^^^^^^^^^^
  File "/root/.local/lib/python3.11/site-packages/telegram/ext/_extbot.py", line 676, in get_updates
    updates = await super().get_updates(
              ^^^^^^^^^^^^^^^^^^^^^^^^^^
  File "/root/.local/lib/python3.11/site-packages/telegram/_bot.py", line 4780, in get_updates
    await self._post(
  File "/root/.local/lib/python3.11/site-packages/telegram/_bot.py", line 703, in _post
    return await self._do_post(
           ^^^^^^^^^^^^^^^^^^^^
  File "/root/.local/lib/python3.11/site-packages/telegram/ext/_extbot.py", line 372, in _do_post
    return await super()._do_post(
           ^^^^^^^^^^^^^^^^^^^^^^^
  File "/root/.local/lib/python3.11/site-packages/telegram/_bot.py", line 732, in _do_post
    result = await request.post(
             ^^^^^^^^^^^^^^^^^^^
  File "/root/.local/lib/python3.11/site-packages/telegram/request/_baserequest.py", line 198, in post
    result = await self._request_wrapper(
             ^^^^^^^^^^^^^^^^^^^^^^^^^^^^
  File "/root/.local/lib/python3.11/site-packages/telegram/request/_baserequest.py", line 375, in _request_wrapper
    raise exception
telegram.error.Conflict: Conflict: can't use getUpdates method while webhook is active; use deleteWebhook to delete the webhook first
2025-10-04 09:16:33,793 - telegram.ext.Updater - ERROR - Exception happened while polling for updates.
Traceback (most recent call last):
  File "/root/.local/lib/python3.11/site-packages/telegram/ext/_utils/networkloop.py", line 134, in network_retry_loop
    await do_action()
  File "/root/.local/lib/python3.11/site-packages/telegram/ext/_utils/networkloop.py", line 127, in do_action
    action_cb_task.result()
  File "/root/.local/lib/python3.11/site-packages/telegram/ext/_updater.py", line 340, in polling_action_cb
    updates = await self.bot.get_updates(
              ^^^^^^^^^^^^^^^^^^^^^^^^^^^
  File "/root/.local/lib/python3.11/site-packages/telegram/ext/_extbot.py", line 676, in get_updates
    updates = await super().get_updates(
              ^^^^^^^^^^^^^^^^^^^^^^^^^^
  File "/root/.local/lib/python3.11/site-packages/telegram/_bot.py", line 4780, in get_updates
    await self._post(
  File "/root/.local/lib/python3.11/site-packages/telegram/_bot.py", line 703, in _post
    return await self._do_post(
           ^^^^^^^^^^^^^^^^^^^^
  File "/root/.local/lib/python3.11/site-packages/telegram/ext/_extbot.py", line 372, in _do_post
    return await super()._do_post(
           ^^^^^^^^^^^^^^^^^^^^^^^
  File "/root/.local/lib/python3.11/site-packages/telegram/_bot.py", line 732, in _do_post
    result = await request.post(
             ^^^^^^^^^^^^^^^^^^^
  File "/root/.local/lib/python3.11/site-packages/telegram/request/_baserequest.py", line 198, in post
    result = await self._request_wrapper(
             ^^^^^^^^^^^^^^^^^^^^^^^^^^^^
  File "/root/.local/lib/python3.11/site-packages/telegram/request/_baserequest.py", line 375, in _request_wrapper
    raise exception
telegram.error.Conflict: Conflict: can't use getUpdates method while webhook is active; use deleteWebhook to delete the webhook first
2025-10-04 09:16:39,350 - telegram.ext.Updater - ERROR - Exception happened while polling for updates.
Traceback (most recent call last):
  File "/root/.local/lib/python3.11/site-packages/telegram/ext/_utils/networkloop.py", line 134, in network_retry_loop
    await do_action()
  File "/root/.local/lib/python3.11/site-packages/telegram/ext/_utils/networkloop.py", line 127, in do_action
    action_cb_task.result()
  File "/root/.local/lib/python3.11/site-packages/telegram/ext/_updater.py", line 340, in polling_action_cb
    updates = await self.bot.get_updates(
              ^^^^^^^^^^^^^^^^^^^^^^^^^^^
  File "/root/.local/lib/python3.11/site-packages/telegram/ext/_extbot.py", line 676, in get_updates
    updates = await super().get_updates(
              ^^^^^^^^^^^^^^^^^^^^^^^^^^
  File "/root/.local/lib/python3.11/site-packages/telegram/_bot.py", line 4780, in get_updates
    await self._post(
  File "/root/.local/lib/python3.11/site-packages/telegram/_bot.py", line 703, in _post
    return await self._do_post(
           ^^^^^^^^^^^^^^^^^^^^
  File "/root/.local/lib/python3.11/site-packages/telegram/ext/_extbot.py", line 372, in _do_post
    return await super()._do_post(
           ^^^^^^^^^^^^^^^^^^^^^^^
  File "/root/.local/lib/python3.11/site-packages/telegram/_bot.py", line 732, in _do_post
    result = await request.post(
             ^^^^^^^^^^^^^^^^^^^
  File "/root/.local/lib/python3.11/site-packages/telegram/request/_baserequest.py", line 198, in post
    result = await self._request_wrapper(
             ^^^^^^^^^^^^^^^^^^^^^^^^^^^^
  File "/root/.local/lib/python3.11/site-packages/telegram/request/_baserequest.py", line 375, in _request_wrapper
    raise exception
telegram.error.Conflict: Conflict: can't use getUpdates method while webhook is active; use deleteWebhook to delete the webhook first
2025-10-04 09:16:47,460 - telegram.ext.Updater - ERROR - Exception happened while polling for updates.
Traceback (most recent call last):
  File "/root/.local/lib/python3.11/site-packages/telegram/ext/_utils/networkloop.py", line 134, in network_retry_loop
    await do_action()
  File "/root/.local/lib/python3.11/site-packages/telegram/ext/_utils/networkloop.py", line 127, in do_action
    action_cb_task.result()
  File "/root/.local/lib/python3.11/site-packages/telegram/ext/_updater.py", line 340, in polling_action_cb
    updates = await self.bot.get_updates(
              ^^^^^^^^^^^^^^^^^^^^^^^^^^^
  File "/root/.local/lib/python3.11/site-packages/telegram/ext/_extbot.py", line 676, in get_updates
    updates = await super().get_updates(
              ^^^^^^^^^^^^^^^^^^^^^^^^^^
  File "/root/.local/lib/python3.11/site-packages/telegram/_bot.py", line 4780, in get_updates
    await self._post(
  File "/root/.local/lib/python3.11/site-packages/telegram/_bot.py", line 703, in _post
    return await self._do_post(
           ^^^^^^^^^^^^^^^^^^^^
  File "/root/.local/lib/python3.11/site-packages/telegram/ext/_extbot.py", line 372, in _do_post
    return await super()._do_post(
           ^^^^^^^^^^^^^^^^^^^^^^^
  File "/root/.local/lib/python3.11/site-packages/telegram/_bot.py", line 732, in _do_post
    result = await request.post(
             ^^^^^^^^^^^^^^^^^^^
  File "/root/.local/lib/python3.11/site-packages/telegram/request/_baserequest.py", line 198, in post
    result = await self._request_wrapper(
             ^^^^^^^^^^^^^^^^^^^^^^^^^^^^
  File "/root/.local/lib/python3.11/site-packages/telegram/request/_baserequest.py", line 375, in _request_wrapper
    raise exception
telegram.error.Conflict: Conflict: can't use getUpdates method while webhook is active; use deleteWebhook to delete the webhook first
2025-10-04 09:16:50,538 - apscheduler.executors.default - INFO - Running job "track_memory_usage (trigger: interval[0:05:00], next run at: 2025-10-04 09:21:50 UTC)" (scheduled at 2025-10-04 09:16:50.534964+00:00)
2025-10-04 09:16:50,545 - apscheduler.executors.default - INFO - Job "track_memory_usage (trigger: interval[0:05:00], next run at: 2025-10-04 09:21:50 UTC)" executed successfully
2025-10-04 09:16:59,344 - telegram.ext.Updater - ERROR - Exception happened while polling for updates.
Traceback (most recent call last):
  File "/root/.local/lib/python3.11/site-packages/telegram/ext/_utils/networkloop.py", line 134, in network_retry_loop
    await do_action()
  File "/root/.local/lib/python3.11/site-packages/telegram/ext/_utils/networkloop.py", line 127, in do_action
    action_cb_task.result()
  File "/root/.local/lib/python3.11/site-packages/telegram/ext/_updater.py", line 340, in polling_action_cb
    updates = await self.bot.get_updates(
              ^^^^^^^^^^^^^^^^^^^^^^^^^^^
  File "/root/.local/lib/python3.11/site-packages/telegram/ext/_extbot.py", line 676, in get_updates
    updates = await super().get_updates(
              ^^^^^^^^^^^^^^^^^^^^^^^^^^
  File "/root/.local/lib/python3.11/site-packages/telegram/_bot.py", line 4780, in get_updates
    await self._post(
  File "/root/.local/lib/python3.11/site-packages/telegram/_bot.py", line 703, in _post
    return await self._do_post(
           ^^^^^^^^^^^^^^^^^^^^
  File "/root/.local/lib/python3.11/site-packages/telegram/ext/_extbot.py", line 372, in _do_post
    return await super()._do_post(
           ^^^^^^^^^^^^^^^^^^^^^^^
  File "/root/.local/lib/python3.11/site-packages/telegram/_bot.py", line 732, in _do_post
    result = await request.post(
             ^^^^^^^^^^^^^^^^^^^
  File "/root/.local/lib/python3.11/site-packages/telegram/request/_baserequest.py", line 198, in post
    result = await self._request_wrapper(
             ^^^^^^^^^^^^^^^^^^^^^^^^^^^^
  File "/root/.local/lib/python3.11/site-packages/telegram/request/_baserequest.py", line 375, in _request_wrapper
    raise exception
telegram.error.Conflict: Conflict: can't use getUpdates method while webhook is active; use deleteWebhook to delete the webhook first